
Epoch 1/20
                                                 /opt/anaconda3/envs/auto/lib/python3.10/site-packages/torch/nn/modules/loss.py:610: UserWarning: Using a target size (torch.Size([32])) that is different to the input size (torch.Size([32, 1])). This will likely lead to incorrect results due to broadcasting. Please ensure they have the same size.
  return F.mse_loss(input, target, reduction=self.reduction)
                                                           /opt/anaconda3/envs/auto/lib/python3.10/site-packages/torch/nn/modules/loss.py:610: UserWarning: Using a target size (torch.Size([26])) that is different to the input size (torch.Size([26, 1])). This will likely lead to incorrect results due to broadcasting. Please ensure they have the same size.
  return F.mse_loss(input, target, reduction=self.reduction)
Training: 100%|██████████| 122/122 [00:02<00:00, 54.90it/s]
Validation:   0%|          | 0/27 [00:00<?, ?it/s]/opt/anaconda3/envs/auto/lib/python3.10/site-packages/torch/nn/modules/loss.py:610: UserWarning: Using a target size (torch.Size([3])) that is different to the input size (torch.Size([3, 1])). This will likely lead to incorrect results due to broadcasting. Please ensure they have the same size.
  return F.mse_loss(input, target, reduction=self.reduction)
Training: 100%|██████████| 122/122 [00:02<00:00, 54.72it/s]
Training: 100%|██████████| 122/122 [00:02<00:00, 58.18it/s]
Training: 100%|██████████| 122/122 [00:02<00:00, 58.46it/s]
Training: 100%|██████████| 122/122 [00:02<00:00, 57.85it/s]
	Train Loss 7.1442	 Learning Rate 0.0004830
	Val Loss 0.7800

Epoch 2/20
Training: 100%|██████████| 122/122 [00:02<00:00, 57.93it/s]
Training: 100%|██████████| 122/122 [00:02<00:00, 57.37it/s]
                                                  
                                                  
Training:  98%|█████████▊| 120/122 [00:02<00:00, 56.62it/s]
	Train Loss 0.4292	 Learning Rate 0.0010675
	Val Loss 0.4122

Epoch 3/20
Training:  98%|█████████▊| 120/122 [00:02<00:00, 58.64it/s]
	Train Loss 0.4004	 Learning Rate 0.0019628
	Val Loss 0.4433

Epoch 4/20
Training:  98%|█████████▊| 120/122 [00:02<00:00, 59.30it/s]
	Train Loss 0.4003	 Learning Rate 0.0030608
	Val Loss 0.4157

Epoch 5/20
Training:  98%|█████████▊| 120/122 [00:02<00:00, 58.27it/s]
	Train Loss 0.4031	 Learning Rate 0.0042287
	Val Loss 0.4199

Epoch 6/20
Training:  98%|█████████▊| 120/122 [00:02<00:00, 58.04it/s]
	Train Loss 0.4087	 Learning Rate 0.0053256
	Val Loss 0.3995

Epoch 7/20
Training:  98%|█████████▊| 120/122 [00:02<00:00, 57.25it/s]
	Train Loss 0.4080	 Learning Rate 0.0062187
	Val Loss 0.3982

Epoch 8/20
Training:  98%|█████████▊| 120/122 [00:02<00:00, 55.51it/s]
	Train Loss 0.4187	 Learning Rate 0.0068003
	Val Loss 0.4010

Epoch 9/20
Training:  98%|█████████▊| 120/122 [00:02<00:00, 56.22it/s]
	Train Loss 0.4172	 Learning Rate 0.0070000
	Val Loss 0.4013

Epoch 10/20
Training:  98%|█████████▊| 120/122 [00:02<00:00, 57.39it/s]
	Train Loss 0.4204	 Learning Rate 0.0068559
	Val Loss 0.4145

Epoch 11/20
Training:  98%|█████████▊| 120/122 [00:02<00:00, 57.63it/s]
	Train Loss 0.4069	 Learning Rate 0.0064400
	Val Loss 0.3981

Epoch 12/20
Training:  98%|█████████▊| 120/122 [00:02<00:00, 56.78it/s]
	Train Loss 0.4040	 Learning Rate 0.0057858
	Val Loss 0.3971

Epoch 13/20
Training:  98%|█████████▊| 120/122 [00:02<00:00, 55.97it/s]
	Train Loss 0.4040	 Learning Rate 0.0049465
	Val Loss 0.3975

Epoch 14/20
    obj = guarded_eval(█▊| 120/122 [00:02<00:00, 56.85it/s]
	Train Loss 0.3972	 Learning Rate 0.0039900
	Val Loss 0.4256

Epoch 15/20
  File "/opt/anaconda3/envs/auto/lib/python3.10/site-packages/IPython/core/guarded_eval.py", line 389, in guarded_eval
	Train Loss 0.3991	 Learning Rate 0.0029938
	Val Loss 0.4017

Epoch 16/20
    return eval_node(expression, context)<00:00, 55.69it/s]
	Train Loss 0.3986	 Learning Rate 0.0020386
	Val Loss 0.4196

Epoch 17/20
  File "/opt/anaconda3/envs/auto/lib/python3.10/site-packages/IPython/core/guarded_eval.py", line 499, in eval_node
	Train Loss 0.3963	 Learning Rate 0.0012018
	Val Loss 0.4039

Epoch 18/20
    return eval_node(node.body, context)2<00:00, 55.89it/s]
	Train Loss 0.3942	 Learning Rate 0.0005512
	Val Loss 0.3984

Epoch 19/20
  File "/opt/anaconda3/envs/auto/lib/python3.10/site-packages/IPython/core/guarded_eval.py", line 613, in eval_node
	Train Loss 0.3933	 Learning Rate 0.0001395
	Val Loss 0.3980

Epoch 20/20
    func = eval_node(node.func, context)?, ?it/s]
  File "/opt/anaconda3/envs/auto/lib/python3.10/site-packages/IPython/core/guarded_eval.py", line 596, in eval_node
    return _eval_node_name(node.id, context)
  File "/opt/anaconda3/envs/auto/lib/python3.10/site-packages/IPython/core/guarded_eval.py", line 729, in _eval_node_name
    raise NameError(f"{node_id} not found in locals, globals, nor builtins")
NameError: odel not found in locals, globals, nor builtins

During handling of the above exception, another exception occurred:

Traceback (most recent call last):
  File "/opt/anaconda3/envs/auto/lib/python3.10/site-packages/IPython/core/completer.py", line 3246, in _complete
    result = matcher(context)
  File "/opt/anaconda3/envs/auto/lib/python3.10/site-packages/IPython/core/completer.py", line 2365, in python_matcher
    matches, fragment = self._attr_matches(text, include_prefix=False)
  File "/opt/anaconda3/envs/auto/lib/python3.10/site-packages/IPython/core/completer.py", line 1156, in _attr_matches
    obj = self._evaluate_expr(expr)
  File "/opt/anaconda3/envs/auto/lib/python3.10/site-packages/IPython/core/completer.py", line 1258, in _evaluate_expr
    expr = self._trim_expr(expr)
  File "/opt/anaconda3/envs/auto/lib/python3.10/site-packages/IPython/core/completer.py", line 1229, in _trim_expr
    expr = res.body[0].value
AttributeError: 'Delete' object has no attribute 'value'
Traceback (most recent call last):
  File "/opt/anaconda3/envs/auto/lib/python3.10/site-packages/IPython/core/completer.py", line 1242, in _evaluate_expr
    obj = guarded_eval(
  File "/opt/anaconda3/envs/auto/lib/python3.10/site-packages/IPython/core/guarded_eval.py", line 389, in guarded_eval
    return eval_node(expression, context)
  File "/opt/anaconda3/envs/auto/lib/python3.10/site-packages/IPython/core/guarded_eval.py", line 499, in eval_node
    return eval_node(node.body, context)
  File "/opt/anaconda3/envs/auto/lib/python3.10/site-packages/IPython/core/guarded_eval.py", line 613, in eval_node
    func = eval_node(node.func, context)
  File "/opt/anaconda3/envs/auto/lib/python3.10/site-packages/IPython/core/guarded_eval.py", line 596, in eval_node
    return _eval_node_name(node.id, context)
  File "/opt/anaconda3/envs/auto/lib/python3.10/site-packages/IPython/core/guarded_eval.py", line 729, in _eval_node_name
    raise NameError(f"{node_id} not found in locals, globals, nor builtins")
NameError: odel not found in locals, globals, nor builtins

During handling of the above exception, another exception occurred:

Traceback (most recent call last):
  File "/opt/anaconda3/envs/auto/lib/python3.10/site-packages/IPython/core/completer.py", line 3246, in _complete
    result = matcher(context)
  File "/opt/anaconda3/envs/auto/lib/python3.10/site-packages/IPython/core/completer.py", line 2365, in python_matcher
    matches, fragment = self._attr_matches(text, include_prefix=False)
  File "/opt/anaconda3/envs/auto/lib/python3.10/site-packages/IPython/core/completer.py", line 1156, in _attr_matches
    obj = self._evaluate_expr(expr)
  File "/opt/anaconda3/envs/auto/lib/python3.10/site-packages/IPython/core/completer.py", line 1258, in _evaluate_expr
    expr = self._trim_expr(expr)
  File "/opt/anaconda3/envs/auto/lib/python3.10/site-packages/IPython/core/completer.py", line 1229, in _trim_expr
    expr = res.body[0].value
AttributeError: 'Delete' object has no attribute 'value'
Traceback (most recent call last):
  File "/opt/anaconda3/envs/auto/lib/python3.10/site-packages/IPython/core/completer.py", line 1242, in _evaluate_expr
    obj = guarded_eval(
  File "/opt/anaconda3/envs/auto/lib/python3.10/site-packages/IPython/core/guarded_eval.py", line 389, in guarded_eval
    return eval_node(expression, context)
  File "/opt/anaconda3/envs/auto/lib/python3.10/site-packages/IPython/core/guarded_eval.py", line 499, in eval_node
    return eval_node(node.body, context)
  File "/opt/anaconda3/envs/auto/lib/python3.10/site-packages/IPython/core/guarded_eval.py", line 613, in eval_node
    func = eval_node(node.func, context)
  File "/opt/anaconda3/envs/auto/lib/python3.10/site-packages/IPython/core/guarded_eval.py", line 596, in eval_node
    return _eval_node_name(node.id, context)
  File "/opt/anaconda3/envs/auto/lib/python3.10/site-packages/IPython/core/guarded_eval.py", line 729, in _eval_node_name
    raise NameError(f"{node_id} not found in locals, globals, nor builtins")
NameError: odel not found in locals, globals, nor builtins

During handling of the above exception, another exception occurred:

Traceback (most recent call last):
  File "/opt/anaconda3/envs/auto/lib/python3.10/site-packages/IPython/core/completer.py", line 3246, in _complete
    result = matcher(context)
  File "/opt/anaconda3/envs/auto/lib/python3.10/site-packages/IPython/core/completer.py", line 2365, in python_matcher
    matches, fragment = self._attr_matches(text, include_prefix=False)
  File "/opt/anaconda3/envs/auto/lib/python3.10/site-packages/IPython/core/completer.py", line 1156, in _attr_matches
    obj = self._evaluate_expr(expr)
  File "/opt/anaconda3/envs/auto/lib/python3.10/site-packages/IPython/core/completer.py", line 1258, in _evaluate_expr
    expr = self._trim_expr(expr)
  File "/opt/anaconda3/envs/auto/lib/python3.10/site-packages/IPython/core/completer.py", line 1229, in _trim_expr
    expr = res.body[0].value
AttributeError: 'Delete' object has no attribute 'value'
Traceback (most recent call last):
  File "/opt/anaconda3/envs/auto/lib/python3.10/site-packages/IPython/core/completer.py", line 1242, in _evaluate_expr
    obj = guarded_eval(
  File "/opt/anaconda3/envs/auto/lib/python3.10/site-packages/IPython/core/guarded_eval.py", line 389, in guarded_eval
    return eval_node(expression, context)
  File "/opt/anaconda3/envs/auto/lib/python3.10/site-packages/IPython/core/guarded_eval.py", line 499, in eval_node
    return eval_node(node.body, context)
  File "/opt/anaconda3/envs/auto/lib/python3.10/site-packages/IPython/core/guarded_eval.py", line 613, in eval_node
    func = eval_node(node.func, context)
  File "/opt/anaconda3/envs/auto/lib/python3.10/site-packages/IPython/core/guarded_eval.py", line 596, in eval_node
    return _eval_node_name(node.id, context)
  File "/opt/anaconda3/envs/auto/lib/python3.10/site-packages/IPython/core/guarded_eval.py", line 729, in _eval_node_name
    raise NameError(f"{node_id} not found in locals, globals, nor builtins")
NameError: odel not found in locals, globals, nor builtins

During handling of the above exception, another exception occurred:

Traceback (most recent call last):
  File "/opt/anaconda3/envs/auto/lib/python3.10/site-packages/IPython/core/completer.py", line 3246, in _complete
    result = matcher(context)
  File "/opt/anaconda3/envs/auto/lib/python3.10/site-packages/IPython/core/completer.py", line 2365, in python_matcher
    matches, fragment = self._attr_matches(text, include_prefix=False)
  File "/opt/anaconda3/envs/auto/lib/python3.10/site-packages/IPython/core/completer.py", line 1156, in _attr_matches
    obj = self._evaluate_expr(expr)
  File "/opt/anaconda3/envs/auto/lib/python3.10/site-packages/IPython/core/completer.py", line 1258, in _evaluate_expr
    expr = self._trim_expr(expr)
  File "/opt/anaconda3/envs/auto/lib/python3.10/site-packages/IPython/core/completer.py", line 1229, in _trim_expr
    expr = res.body[0].value
AttributeError: 'Delete' object has no attribute 'value'
Traceback (most recent call last):
  File "/opt/anaconda3/envs/auto/lib/python3.10/site-packages/IPython/core/completer.py", line 1242, in _evaluate_expr
    obj = guarded_eval(
  File "/opt/anaconda3/envs/auto/lib/python3.10/site-packages/IPython/core/guarded_eval.py", line 389, in guarded_eval
    return eval_node(expression, context)
  File "/opt/anaconda3/envs/auto/lib/python3.10/site-packages/IPython/core/guarded_eval.py", line 499, in eval_node
    return eval_node(node.body, context)
  File "/opt/anaconda3/envs/auto/lib/python3.10/site-packages/IPython/core/guarded_eval.py", line 613, in eval_node
    func = eval_node(node.func, context)
  File "/opt/anaconda3/envs/auto/lib/python3.10/site-packages/IPython/core/guarded_eval.py", line 596, in eval_node
    return _eval_node_name(node.id, context)
  File "/opt/anaconda3/envs/auto/lib/python3.10/site-packages/IPython/core/guarded_eval.py", line 729, in _eval_node_name
    raise NameError(f"{node_id} not found in locals, globals, nor builtins")
NameError: odel not found in locals, globals, nor builtins

During handling of the above exception, another exception occurred:

Traceback (most recent call last):
  File "/opt/anaconda3/envs/auto/lib/python3.10/site-packages/IPython/core/completer.py", line 3246, in _complete
    result = matcher(context)
  File "/opt/anaconda3/envs/auto/lib/python3.10/site-packages/IPython/core/completer.py", line 2365, in python_matcher
    matches, fragment = self._attr_matches(text, include_prefix=False)
  File "/opt/anaconda3/envs/auto/lib/python3.10/site-packages/IPython/core/completer.py", line 1156, in _attr_matches
    obj = self._evaluate_expr(expr)
  File "/opt/anaconda3/envs/auto/lib/python3.10/site-packages/IPython/core/completer.py", line 1258, in _evaluate_expr
    expr = self._trim_expr(expr)
  File "/opt/anaconda3/envs/auto/lib/python3.10/site-packages/IPython/core/completer.py", line 1229, in _trim_expr
    expr = res.body[0].value
AttributeError: 'Delete' object has no attribute 'value'
Traceback (most recent call last):
  File "/opt/anaconda3/envs/auto/lib/python3.10/site-packages/IPython/core/completer.py", line 1242, in _evaluate_expr
    obj = guarded_eval(
  File "/opt/anaconda3/envs/auto/lib/python3.10/site-packages/IPython/core/guarded_eval.py", line 389, in guarded_eval
    return eval_node(expression, context)
  File "/opt/anaconda3/envs/auto/lib/python3.10/site-packages/IPython/core/guarded_eval.py", line 499, in eval_node
    return eval_node(node.body, context)
  File "/opt/anaconda3/envs/auto/lib/python3.10/site-packages/IPython/core/guarded_eval.py", line 613, in eval_node
    func = eval_node(node.func, context)
  File "/opt/anaconda3/envs/auto/lib/python3.10/site-packages/IPython/core/guarded_eval.py", line 596, in eval_node
    return _eval_node_name(node.id, context)
  File "/opt/anaconda3/envs/auto/lib/python3.10/site-packages/IPython/core/guarded_eval.py", line 729, in _eval_node_name
    raise NameError(f"{node_id} not found in locals, globals, nor builtins")
NameError: odel not found in locals, globals, nor builtins

During handling of the above exception, another exception occurred:

Traceback (most recent call last):
  File "/opt/anaconda3/envs/auto/lib/python3.10/site-packages/IPython/core/completer.py", line 3246, in _complete
    result = matcher(context)
  File "/opt/anaconda3/envs/auto/lib/python3.10/site-packages/IPython/core/completer.py", line 2365, in python_matcher
    matches, fragment = self._attr_matches(text, include_prefix=False)
  File "/opt/anaconda3/envs/auto/lib/python3.10/site-packages/IPython/core/completer.py", line 1156, in _attr_matches
    obj = self._evaluate_expr(expr)
  File "/opt/anaconda3/envs/auto/lib/python3.10/site-packages/IPython/core/completer.py", line 1258, in _evaluate_expr
    expr = self._trim_expr(expr)
  File "/opt/anaconda3/envs/auto/lib/python3.10/site-packages/IPython/core/completer.py", line 1229, in _trim_expr
    expr = res.body[0].value
AttributeError: 'Delete' object has no attribute 'value'
Traceback (most recent call last):
  File "/opt/anaconda3/envs/auto/lib/python3.10/site-packages/IPython/core/completer.py", line 1242, in _evaluate_expr
    obj = guarded_eval(
  File "/opt/anaconda3/envs/auto/lib/python3.10/site-packages/IPython/core/guarded_eval.py", line 389, in guarded_eval
    return eval_node(expression, context)
  File "/opt/anaconda3/envs/auto/lib/python3.10/site-packages/IPython/core/guarded_eval.py", line 499, in eval_node
    return eval_node(node.body, context)
  File "/opt/anaconda3/envs/auto/lib/python3.10/site-packages/IPython/core/guarded_eval.py", line 613, in eval_node
    func = eval_node(node.func, context)
  File "/opt/anaconda3/envs/auto/lib/python3.10/site-packages/IPython/core/guarded_eval.py", line 596, in eval_node
    return _eval_node_name(node.id, context)
  File "/opt/anaconda3/envs/auto/lib/python3.10/site-packages/IPython/core/guarded_eval.py", line 729, in _eval_node_name
    raise NameError(f"{node_id} not found in locals, globals, nor builtins")
NameError: odel not found in locals, globals, nor builtins

During handling of the above exception, another exception occurred:

Traceback (most recent call last):
  File "/opt/anaconda3/envs/auto/lib/python3.10/site-packages/IPython/core/completer.py", line 3246, in _complete
    result = matcher(context)
  File "/opt/anaconda3/envs/auto/lib/python3.10/site-packages/IPython/core/completer.py", line 2365, in python_matcher
    matches, fragment = self._attr_matches(text, include_prefix=False)
  File "/opt/anaconda3/envs/auto/lib/python3.10/site-packages/IPython/core/completer.py", line 1156, in _attr_matches
    obj = self._evaluate_expr(expr)
  File "/opt/anaconda3/envs/auto/lib/python3.10/site-packages/IPython/core/completer.py", line 1258, in _evaluate_expr
    expr = self._trim_expr(expr)
  File "/opt/anaconda3/envs/auto/lib/python3.10/site-packages/IPython/core/completer.py", line 1229, in _trim_expr
    expr = res.body[0].value
AttributeError: 'Delete' object has no attribute 'value'
[34m[1mwandb[0m: [32m[41mERROR[0m The nbformat package was not found. It is required to save notebook history.
